Workbook

Sheet Raw Data
A1: Price | B1: Address | C1: City | D1: Zipcode | E1: State | F1: Bedrooms | G1: Bathrooms | H1: Area (sqft) | I1: Lot Size(sqft) | J1: Year Built | K1: Days on Market | L1: Property Type | M1: MLS ID | N1: Listing Agent | O1: Status | P1: Listing URL
A2: $554,217 | B2: 5926 Oak Ave, San Diego, CA 65383 | C2: San Diego | D2: 65383 | E2: CA | F2: 1 bds | G2: 3 ba | H2: 772 | I2: 4757 | J2: 1959 | K2: 101 | L2: Townhouse | M2: Z104635 | N2: Alex Johnson - Compass | O2: For Sale | P2: https://www.zillow.com/homedetails/80374762_zpid/
A3: $164,454 | B3: 9583 Oak Ave, Fresno, IL 79339 | C3: Fresno | D3: 79339 | E3: IL | F3: 1 bds | G3: 1 ba | H3: 2348 | I3: 3615 | J3: 1969 | K3: 46 | L3: Apartment | M3: Z535721 | N3: Emily Davis - Century 21 | O3: Sold | P3: https://www.zillow.com/homedetails/86143665_zpid/
A4: $1,249,331 | B4: 8224 Oak Ave, Sacramento, TX 87393 | C4: Sacramento | D4: 87393 | E4: TX | F4: 6 bds | G4: 1 ba | H4: 3630 | I4: 9369 | J4: 1990 | K4: 59 | L4: Townhouse | M4: Z900458 | N4: Mike Lee - Coldwell Banker | O4: For Sale | P4: https://www.zillow.com/homedetails/86143665_zpid/
A5: $189,267 | B5: 232 Oak Ave, Fresno, TX 38666 | C5: Fresno | D5: 38666 | E5: TX | F5: 2 bds | G5: 1 ba | H5: 605 | I5: 8804 | J5: 1958 | K5: 119 | L5: Apartment | M5: Z318589 | N5: John Doe - RE/MAX | O5: Pending | P5: https://www.zillow.com/homedetails/39318132_zpid/
A6: $465,778 | B6: 5446 Pine Rd, Los Angeles, CA 23989 | C6: Los Angeles | D6: 23989 | E6: CA | F6: 3 bds | G6: 2 ba | H6: 1711 | I6: 9260 | J6: 2020 | K6: 26 | L6: Townhouse | M6: Z899716 | N6: John Doe - RE/MAX | O6: Pending | P6: https://www.zillow.com/homedetails/22454634_zpid/
A7: $738,357 | B7: 9202 Maple Dr, Sacramento, NY 71318 | C7: Sacramento | D7: 71318 | E7: NY | F7: 5 bds | G7: 3 ba | H7: 1177 | I7: 8317 | J7: 2015 | K7: 35 | L7: Multi-Family | M7: Z865468 | N7: Jane Smith - Keller Williams | O7: Pending | P7: https://www.zillow.com/homedetails/90690049_zpid/
A8: $1,325,395 | B8: 2698 Elm St, Sacramento, NY 57421 | C8: Sacramento | D8: 57421 | E8: NY | F8: 6 bds | G8: 1 ba | H8: 1990 | I8: 5592 | J8: 2012 | K8: 94 | L8: Townhouse | M8: Z689873 | N8: Alex Johnson - Compass | O8: Pending | P8: https://www.zillow.com/homedetails/99288749_zpid/
A9: $1,158,003 | B9: 2118 Main St, San Diego, IL 64361 | C9: San Diego | D9: 64361 | E9: IL | F9: 2 bds | G9: 2 ba | H9: 1008 | I9: 6010 | J9: 1975 | K9: 75 | L9: Townhouse | M9: Z329631 | N9: John Doe - RE/MAX | O9: For Sale | P9: https://www.zillow.com/homedetails/91922548_zpid/
A10: $240,095 | B10: 9474 Main St, San Francisco, FL 13227 | C10: San Francisco | D10: 13227 | E10: FL | F10: 6 bds | G10: 2 ba | H10: 929 | I10: 5449 | J10: 1975 | K10: 79 | L10: Townhouse | M10: Z839936 | N10: John Doe - RE/MAX | O10: Pending | P10: https://www.zillow.com/homedetails/79694016_zpid/
A11: $1,356,448 | B11: 8803 Maple Dr, San Diego, NY 57397 | C11: San Diego | D11: 57397 | E11: NY | F11: 2 bds | G11: 3 ba | H11: 2094 | I11: 2179 | J11: 1970 | K11: 111 | L11: Multi-Family | M11: Z264011 | N11: John Doe - RE/MAX | O11: Pending | P11: https://www.zillow.com/homedetails/13312383_zpid/
A12: $678,604 | B12: 7535 Elm St, San Diego, FL 70072 | C12: San Diego | D12: 70072 | E12: FL | F12: 3 bds | G12: 3 ba | H12: 2350 | I12: 3341 | J12: 2013 | K12: 25 | L12: Multi-Family | M12: Z298501 | N12: John Doe - RE/MAX | O12: Pending | P12: https://www.zillow.com/homedetails/27502592_zpid/
A13: $1,264,926 | B13: 413 Main St, Fresno, CA 57401 | C13: Fresno | D13: 57401 | E13: CA | F13: 3 bds | G13: 1 ba | H13: 2407 | I13: 2609 | J13: 1989 | K13: 79 | L13: Apartment | M13: Z282442 | N13: Emily Davis - Century 21 | O13: Sold | P13: https://www.zillow.com/homedetails/63532546_zpid/
... A3001: $712,029 | B3001: 4392 Maple Dr, Los Angeles, NY 89198 | C3001: Los Angeles | D3001: 89198 | E3001: NY | F3001: 4 bds | G3001: 3 ba | H3001: 2967 | I3001: 8071 | J3001: 1985 | K3001: 32 | L3001: Condo | M3001: Z876426 | N3001: Alex Johnson - Compass | O3001: For Sale | P3001: https://www.zillow.com/homedetails/64854326_zpid/

Sheet Analysis
A1: Price | B1: Address | C1: City | D1: Zipcode | E1: State | F1: Bedrooms | G1: Bathrooms | H1: Area (Sqft) | I1: Lot Size(Sqft) | J1: Year Built | K1: Days on Market | L1: Property Type | M1: MLS ID | N1: Listing Agent | O1: Status | P1: Duplicated MLS | Q1: Duplicacy status | R1: Area Category | S1: Age of Property | T1: Age Category
A2: 554217 | B2: 5926 Oak Ave, San Diego, CA 65383 | C2: San Diego | D2: 65383 | E2: CA | F2: 1 bds | G2: 3 ba | H2: 772 | I2: 4757 | J2: 1959 | K2: 101 | L2: Townhouse | M2: Z104635 | N2: Alex Johnson - Compass | O2: For Sale | P2: =COUNTIF(Analysis!$M$1:$M$3001,Analysis!$M2) -> 1 | Q2: =IF(COUNTIF(Analysis!$M$2:$M$3001,Analysis!$M2)>1,"Duplicate","OK") -> OK | R2: =IFS( AND(H2>=600, H2<1600),"600-1600", AND(H2>=1600, H2<2600),"1600-2600", AND(H2>=2600, H2<3600),"2600-3600", H2>=3600,"3600+" ) -> 600-1600 | S2: =year(TODAY())-J2 -> 67 | T2: =ifs(AND(S2>=0,S2<=10),"New",AND(S2>10,S2<=30),"Mid",AND(S2>30,S2<=60),"Old",S2>60,"Very Old") -> Very Old
A3: 100866 | B3: 1395 Elm St, Fresno, NY 47843 | C3: Fresno | D3: 47843 | E3: NY | F3: 1 bds | G3: 1 ba | H3: 2107 | I3: 6485 | J3: 2012 | K3: 10 | L3: Apartment | M3: Z577065 | N3: Mike Lee - Coldwell Banker | O3: Sold | P3: =COUNTIF(Analysis!$M$1:$M$3001,Analysis!$M136) -> 1 | Q3: =IF(COUNTIF(Analysis!$M$2:$M$3001,Analysis!$M136)>1,"Duplicate","OK") -> OK | R3: =IFS( AND(H3>=600, H3<1600),"600-1600", AND(H3>=1600, H3<2600),"1600-2600", AND(H3>=2600, H3<3600),"2600-3600", H3>=3600,"3600+" ) -> 1600-2600 | S3: =year(TODAY())-J3 -> 14 | T3: =ifs(AND(S3>=0,S3<=10),"New",AND(S3>10,S3<=30),"Mid",AND(S3>30,S3<=60),"Old",S3>60,"Very Old") -> Mid
A4: 1249331 | B4: 9583 Oak Ave, Fresno, IL 79339 | C4: Sacramento | D4: 87393 | E4: TX | F4: 6 bds | G4: 1 ba | H4: 3630 | I4: 9369 | J4: 1990 | K4: 59 | L4: Townhouse | M4: Z900458 | N4: Mike Lee - Coldwell Banker | O4: For Sale | P4: =COUNTIF(Analysis!$M$1:$M$3001,Analysis!$M4) -> 1 | Q4: =IF(COUNTIF(Analysis!$M$2:$M$3001,Analysis!$M4)>1,"Duplicate","OK") -> OK | R4: =IFS( AND(H4>=600, H4<1600),"600-1600", AND(H4>=1600, H4<2600),"1600-2600", AND(H4>=2600, H4<3600),"2600-3600", H4>=3600,"3600+" ) -> 3600+ | S4: =year(TODAY())-J4 -> 36 | T4: =ifs(AND(S4>=0,S4<=10),"New",AND(S4>10,S4<=30),"Mid",AND(S4>30,S4<=60),"Old",S4>60,"Very Old") -> Old | AL4: Status | AM4: No. of Properties
A5: 101833 | B5: 4704 Oak Ave, Fresno, NY 12937 | C5: Fresno | D5: 12937 | E5: NY | F5: 3 bds | G5: 2 ba | H5: 2943 | I5: 5547 | J5: 2017 | K5: 55 | L5: Single Family | M5: Z877137 | N5: Mike Lee - Coldwell Banker | O5: Pending | P5: =COUNTIF(Analysis!$M$1:$M$3001,Analysis!$M2470) -> 1 | Q5: =IF(COUNTIF(Analysis!$M$2:$M$3001,Analysis!$M2470)>1,"Duplicate","OK") -> OK | R5: =IFS( AND(H5>=600, H5<1600),"600-1600", AND(H5>=1600, H5<2600),"1600-2600", AND(H5>=2600, H5<3600),"2600-3600", H5>=3600,"3600+" ) -> 2600-3600 | S5: =year(TODAY())-J5 -> 9 | T5: =ifs(AND(S5>=0,S5<=10),"New",AND(S5>10,S5<=30),"Mid",AND(S5>30,S5<=60),"Old",S5>60,"Very Old") -> New | AL5: For Sale | AM5: =COUNTIF(Listings[Status],AL5) -> 957 | AN5: =AM5/AM8*100 -> 31.9 | BH5: Price | BI5: Address | BJ5: City | BK5: Zipcode | BL5: State | BM5: Bedrooms | BN5: Bathrooms | BO5: Area (Sqft) | BP5: Lot Size | BQ5: Year Built | BR5: Days on Market | BS5: Property Type | BT5: MLS ID | BU5: Listing Agent | BV5: Status | BW5: Duplicated MLS | BX5: Duplicacy status
A6: 465778 | B6: 5446 Pine Rd, Los Angeles, CA 23989 | C6: Los Angeles | D6: 23989 | E6: CA | F6: 3 bds | G6: 2 ba | H6: 1711 | I6: 9260 | J6: 2020 | K6: 26 | L6: Townhouse | M6: Z899716 | N6: John Doe - RE/MAX | O6: Pending | P6: =COUNTIF(Analysis!$M$1:$M$3001,Analysis!$M6) -> 1 | Q6: =IF(COUNTIF(Analysis!$M$2:$M$3001,Analysis!$M6)>1,"Duplicate","OK") -> OK | R6: =IFS( AND(H6>=600, H6<1600),"600-1600", AND(H6>=1600, H6<2600),"1600-2600", AND(H6>=2600, H6<3600),"2600-3600", H6>=3600,"3600+" ) -> 1600-2600 | S6: =year(TODAY())-J6 -> 6 | T6: =ifs(AND(S6>=0,S6<=10),"New",AND(S6>10,S6<=30),"Mid",AND(S6>30,S6<=60),"Old",S6>60,"Very Old") -> New | V6: State | W6: Max Price | Z6: City | AA6: Average Price | AD6: Property Type | AE6: Average Price | AL6: Pending | AM6: =COUNTIF(Analysis!$O$2:$O$3001,AL6) -> 998 | AN6: =AM6/AM8*100 -> 33.266667 | BH6: =IFERROR(__xludf.DUMMYFUNCTION("QUERY(Listings,""select * where N = 'Alex Johnson - Compass' and O = 'Sold'"",0)"),282593.0) -> 282593 | BI6: =IFERROR(__xludf.DUMMYFUNCTION("""COMPUTED_VALUE"""),"8789 Oak Ave, San Francisco, TX 99388") -> 8789 Oak Ave, San Francisco, TX 99388 | BJ6: =IFERROR(__xludf.DUMMYFUNCTION("""COMPUTED_VALUE"""),"San Francisco") -> San Francisco | BK6: =IFERROR(__xludf.DUMMYFUNCTION("""COMPUTED_VALUE"""),99388.0) -> 99388 | BL6: =IFERROR(__xludf.DUMMYFUNCTION("""COMPUTED_VALUE"""),"TX") -> TX | BM6: =IFERROR(__xludf.DUMMYFUNCTION("""COMPUTED_VALUE"""),"6 bds") -> 6 bds | BN6: =IFERROR(__xludf.DUMMYFUNCTION("""COMPUTED_VALUE"""),"2 ba") -> 2 ba | BO6: =IFERROR(__xludf.DUMMYFUNCTION("""COMPUTED_VALUE"""),2153.0) -> 2153 | BP6: =IFERROR(__xludf.DUMMYFUNCTION("""COMPUTED_VALUE"""),6999.0) -> 6999 | BQ6: =IFERROR(__xludf.DUMMYFUNCTION("""COMPUTED_VALUE"""),1977.0) -> 1977 | BR6: =IFERROR(__xludf.DUMMYFUNCTION("""COMPUTED_VALUE"""),31.0) -> 31 | BS6: =IFERROR(__xludf.DUMMYFUNCTION("""COMPUTED_VALUE"""),"Single Family") -> Single Family | BT6: =IFERROR(__xludf.DUMMYFUNCTION("""COMPUTED_VALUE"""),"Z620042") -> Z620042 | BU6: =IFERROR(__xludf.DUMMYFUNCTION("""COMPUTED_VALUE"""),"Alex Johnson - Compass") -> Alex Johnson - Compass | BV6: =IFERROR(__xludf.DUMMYFUNCTION("""COMPUTED_VALUE"""),"Sold") -> Sold | BW6: =IFERROR(__xludf.DUMMYFUNCTION("""COMPUTED_VALUE"""),1.0) -> 1 | BX6: =IFERROR(__xludf.DUMMYFUNCTION("""COMPUTED_VALUE"""),"OK") -> OK | BY6: =IFERROR(__xludf.DUMMYFUNCTION("""COMPUTED_VALUE"""),"1600-2600") -> 1600-2600 | BZ6: =IFERROR(__xludf.DUMMYFUNCTION("""COMPUTED_VALUE"""),49.0) -> 49 | CA6: =IFERROR(__xludf.DUMMYFUNCTION("""COMPUTED_VALUE"""),"Old") -> Old
A7: 738357 | B7: 9202 Maple Dr, Sacramento, NY 71318 | C7: Sacramento | D7: 71318 | E7: NY | F7: 5 bds | G7: 3 ba | H7: 1177 | I7: 8317 | J7: 2015 | K7: 35 | L7: Multi-Family | M7: Z865468 | N7: Jane Smith - Keller Williams | O7: Pending | P7: =COUNTIF(Analysis!$M$1:$M$3001,Analysis!$M7) -> 1 | Q7: =IF(COUNTIF(Analysis!$M$2:$M$3001,Analysis!$M7)>1,"Duplicate","OK") -> OK | R7: =IFS( AND(H7>=600, H7<1600),"600-1600", AND(H7>=1600, H7<2600),"1600-2600", AND(H7>=2600, H7<3600),"2600-3600", H7>=3600,"3600+" ) -> 600-1600 | S7: =year(TODAY())-J7 -> 11 | T7: =ifs(AND(S7>=0,S7<=10),"New",AND(S7>10,S7<=30),"Mid",AND(S7>30,S7<=60),"Old",S7>60,"Very Old") -> Mid | V7: CA | W7: =maxifs(Listings[Price],Listings[State],V7) -> 1499218 | Z7: San Diego | AA7: =AVERAGEIF(Listings[City],C2,Listings[Price]) -> 814489.25 | AD7: Townhouse | AE7: =Averageif(Listings[Property Type],AD7,Listings[Price]) -> 813447.35 | AL7: Sold | AM7: =COUNTIF(Listings[Status],AL7) -> 1045 | AN7: =AM7/AM8*100 -> 34.833333 | BH7: =IFERROR(__xludf.DUMMYFUNCTION("""COMPUTED_VALUE"""),1440759.0) -> 1440759 | BI7: =IFERROR(__xludf.DUMMYFUNCTION("""COMPUTED_VALUE"""),"4328 Pine Rd, San Diego, TX 55033") -> 4328 Pine Rd, San Diego, TX 55033 | BJ7: =IFERROR(__xludf.DUMMYFUNCTION("""COMPUTED_VALUE"""),"San Diego") -> San Diego | BK7: =IFERROR(__xludf.DUMMYFUNCTION("""COMPUTED_VALUE"""),55033.0) -> 55033 | BL7: =IFERROR(__xludf.DUMMYFUNCTION("""COMPUTED_VALUE"""),"TX") -> TX | BM7: =IFERROR(__xludf.DUMMYFUNCTION("""COMPUTED_VALUE"""),"5 bds") -> 5 bds | BN7: =IFERROR(__xludf.DUMMYFUNCTION("""COMPUTED_VALUE"""),"3 ba") -> 3 ba | BO7: =IFERROR(__xludf.DUMMYFUNCTION("""COMPUTED_VALUE"""),1012.0) -> 1012 | BP7: =IFERROR(__xludf.DUMMYFUNCTION("""COMPUTED_VALUE"""),6279.0) -> 6279 | BQ7: =IFERROR(__xludf.DUMMYFUNCTION("""COMPUTED_VALUE"""),1954.0) -> 1954 | BR7: =IFERROR(__xludf.DUMMYFUNCTION("""COMPUTED_VALUE"""),94.0) -> 94 | BS7: =IFERROR(__xludf.DUMMYFUNCTION("""COMPUTED_VALUE"""),"Condo") -> Condo | BT7: =IFERROR(__xludf.DUMMYFUNCTION("""COMPUTED_VALUE"""),"Z833664") -> Z833664 | BU7: =IFERROR(__xludf.DUMMYFUNCTION("""COMPUTED_VALUE"""),"Alex Johnson - Compass") -> Alex Johnson - Compass | BV7: =IFERROR(__xludf.DUMMYFUNCTION("""COMPUTED_VALUE"""),"Sold") -> Sold | BW7: =IFERROR(__xludf.DUMMYFUNCTION("""COMPUTED_VALUE"""),1.0) -> 1 | BX7: =IFERROR(__xludf.DUMMYFUNCTION("""COMPUTED_VALUE"""),"OK") -> OK | BY7: =IFERROR(__xludf.DUMMYFUNCTION("""COMPUTED_VALUE"""),"600-1600") -> 600-1600 | BZ7: =IFERROR(__xludf.DUMMYFUNCTION("""COMPUTED_VALUE"""),72.0) -> 72 | CA7: =IFERROR(__xludf.DUMMYFUNCTION("""COMPUTED_VALUE"""),"Very Old") -> Very Old
A8: 1325395 | B8: 2698 Elm St, Sacramento, NY 57421 | C8: Sacramento | D8: 57421 | E8: NY | F8: 6 bds | G8: 1 ba | H8: 1990 | I8: 5592 | J8: 2012 | K8: 94 | L8: Townhouse | M8: Z689873 | N8: Alex Johnson - Compass | O8: Pending | P8: =COUNTIF(Analysis!$M$1:$M$3001,Analysis!$M8) -> 1 | Q8: =IF(COUNTIF(Analysis!$M$2:$M$3001,Analysis!$M8)>1,"Duplicate","OK") -> OK | R8: =IFS( AND(H8>=600, H8<1600),"600-1600", AND(H8>=1600, H8<2600),"1600-2600", AND(H8>=2600, H8<3600),"2600-3600", H8>=3600,"3600+" ) -> 1600-2600 | S8: =year(TODAY())-J8 -> 14 | T8: =ifs(AND(S8>=0,S8<=10),"New",AND(S8>10,S8<=30),"Mid",AND(S8>30,S8<=60),"Old",S8>60,"Very Old") -> Mid | V8: FL | W8: =maxifs(Listings[Price],Listings[State],V8) -> 1496345 | Z8: Fresno | AA8: =AVERAGEIF(Listings[City],C3,Listings[Price]) -> 833497.57 | AD8: Apartment | AE8: =Averageif(Listings[Property Type],AD8,Listings[Price]) -> 825628.62 | AM8: =SUM(AM5:AM7) -> 3000 | BH8: =IFERROR(__xludf.DUMMYFUNCTION("""COMPUTED_VALUE"""),1256611.0) -> 1256611 | BI8: =IFERROR(__xludf.DUMMYFUNCTION("""COMPUTED_VALUE"""),"3492 Pine Rd, Sacramento, CA 23389") -> 3492 Pine Rd, Sacramento, CA 23389 | BJ8: =IFERROR(__xludf.DUMMYFUNCTION("""COMPUTED_VALUE"""),"Sacramento") -> Sacramento | BK8: =IFERROR(__xludf.DUMMYFUNCTION("""COMPUTED_VALUE"""),23389.0) -> 23389 | BL8: =IFERROR(__xludf.DUMMYFUNCTION("""COMPUTED_VALUE"""),"CA") -> CA | BM8: =IFERROR(__xludf.DUMMYFUNCTION("""COMPUTED_VALUE"""),"2 bds") -> 2 bds | BN8: =IFERROR(__xludf.DUMMYFUNCTION("""COMPUTED_VALUE"""),"4 ba") -> 4 ba | BO8: =IFERROR(__xludf.DUMMYFUNCTION("""COMPUTED_VALUE"""),3037.0) -> 3037 | BP8: =IFERROR(__xludf.DUMMYFUNCTION("""COMPUTED_VALUE"""),9989.0) -> 9989 | BQ8: =IFERROR(__xludf.DUMMYFUNCTION("""COMPUTED_VALUE"""),1956.0) -> 1956 | BR8: =IFERROR(__xludf.DUMMYFUNCTION("""COMPUTED_VALUE"""),25.0) -> 25 | BS8: =IFERROR(__xludf.DUMMYFUNCTION("""COMPUTED_VALUE"""),"Townhouse") -> Townhouse | BT8: =IFERROR(__xludf.DUMMYFUNCTION("""COMPUTED_VALUE"""),"Z587830") -> Z587830 | BU8: =IFERROR(__xludf.DUMMYFUNCTION("""COMPUTED_VALUE"""),"Alex Johnson - Compass") -> Alex Johnson - Compass | BV8: =IFERROR(__xludf.DUMMYFUNCTION("""COMPUTED_VALUE"""),"Sold") -> Sold | BW8: =IFERROR(__xludf.DUMMYFUNCTION("""COMPUTED_VALUE"""),1.0) -> 1 | BX8: =IFERROR(__xludf.DUMMYFUNCTION("""COMPUTED_VALUE"""),"OK") -> OK | BY8: =IFERROR(__xludf.DUMMYFUNCTION("""COMPUTED_VALUE"""),"2600-3600") -> 2600-3600 | BZ8: =IFERROR(__xludf.DUMMYFUNCTION("""COMPUTED_VALUE"""),70.0) -> 70 | CA8: =IFERROR(__xludf.DUMMYFUNCTION("""COMPUTED_VALUE"""),"Very Old") -> Very Old
A9: 1158003 | B9: 2118 Main St, San Diego, IL 64361 | C9: San Diego | D9: 64361 | E9: IL | F9: 2 bds | G9: 2 ba | H9: 1008 | I9: 6010 | J9: 1975 | K9: 75 | L9: Townhouse | M9: Z329631 | N9: John Doe - RE/MAX | O9: For Sale | P9: =COUNTIF(Analysis!$M$1:$M$3001,Analysis!$M9) -> 1 | Q9: =IF(COUNTIF(Analysis!$M$2:$M$3001,Analysis!$M9)>1,"Duplicate","OK") -> OK | R9: =IFS( AND(H9>=600, H9<1600),"600-1600", AND(H9>=1600, H9<2600),"1600-2600", AND(H9>=2600, H9<3600),"2600-3600", H9>=3600,"3600+" ) -> 600-1600 | S9: =year(TODAY())-J9 -> 51 | T9: =ifs(AND(S9>=0,S9<=10),"New",AND(S9>10,S9<=30),"Mid",AND(S9>30,S9<=60),"Old",S9>60,"Very Old") -> Old | V9: IL | W9: =maxifs(Listings[Price],Listings[State],V9) -> 1496721 | Z9: Sacramento | AA9: =AVERAGEIF(Listings[City],Z9,Listings[Price]) -> 804244.18 | AD9: Single Family | AE9: =Averageif(Listings[Property Type],AD9,Listings[Price]) -> 824646.21 | BH9: =IFERROR(__xludf.DUMMYFUNCTION("""COMPUTED_VALUE"""),439407.0) -> 439407 | BI9: =IFERROR(__xludf.DUMMYFUNCTION("""COMPUTED_VALUE"""),"1157 Pine Rd, San Francisco, IL 97204") -> 1157 Pine Rd, San Francisco, IL 97204 | BJ9: =IFERROR(__xludf.DUMMYFUNCTION("""COMPUTED_VALUE"""),"San Francisco") -> San Francisco | BK9: =IFERROR(__xludf.DUMMYFUNCTION("""COMPUTED_VALUE"""),97204.0) -> 97204 | BL9: =IFERROR(__xludf.DUMMYFUNCTION("""COMPUTED_VALUE"""),"IL") -> IL | BM9: =IFERROR(__xludf.DUMMYFUNCTION("""COMPUTED_VALUE"""),"2 bds") -> 2 bds | BN9: =IFERROR(__xludf.DUMMYFUNCTION("""COMPUTED_VALUE"""),"4 ba") -> 4 ba | BO9: =IFERROR(__xludf.DUMMYFUNCTION("""COMPUTED_VALUE"""),2796.0) -> 2796 | BP9: =IFERROR(__xludf.DUMMYFUNCTION("""COMPUTED_VALUE"""),7855.0) -> 7855 | BQ9: =IFERROR(__xludf.DUMMYFUNCTION("""COMPUTED_VALUE"""),1969.0) -> 1969 | BR9: =IFERROR(__xludf.DUMMYFUNCTION("""COMPUTED_VALUE"""),15.0) -> 15 | BS9: =IFERROR(__xludf.DUMMYFUNCTION("""COMPUTED_VALUE"""),"Apartment") -> Apartment | BT9: =IFERROR(__xludf.DUMMYFUNCTION("""COMPUTED_VALUE"""),"Z685882") -> Z685882 | BU9: =IFERROR(__xludf.DUMMYFUNCTION("""COMPUTED_VALUE"""),"Alex Johnson - Compass") -> Alex Johnson - Compass | BV9: =IFERROR(__xludf.DUMMYFUNCTION("""COMPUTED_VALUE"""),"Sold") -> Sold | BW9: =IFERROR(__xludf.DUMMYFUNCTION("""COMPUTED_VALUE"""),1.0) -> 1 | BX9: =IFERROR(__xludf.DUMMYFUNCTION("""COMPUTED_VALUE"""),"OK") -> OK | BY9: =IFERROR(__xludf.DUMMYFUNCTION("""COMPUTED_VALUE"""),"2600-3600") -> 2600-3600 | BZ9: =IFERROR(__xludf.DUMMYFUNCTION("""COMPUTED_VALUE"""),57.0) -> 57 | CA9: =IFERROR(__xludf.DUMMYFUNCTION("""COMPUTED_VALUE"""),"Old") -> Old
A10: 240095 | B10: 9474 Main St, San Francisco, FL 13227 | C10: San Francisco | D10: 13227 | E10: FL | F10: 6 bds | G10: 2 ba | H10: 929 | I10: 5449 | J10: 1975 | K10: 79 | L10: Townhouse | M10: Z839936 | N10: John Doe - RE/MAX | O10: Pending | P10: =COUNTIF(Analysis!$M$1:$M$3001,Analysis!$M10) -> 1 | Q10: =IF(COUNTIF(Analysis!$M$2:$M$3001,Analysis!$M10)>1,"Duplicate","OK") -> OK | R10: =IFS( AND(H10>=600, H10<1600),"600-1600", AND(H10>=1600, H10<2600),"1600-2600", AND(H10>=2600, H10<3600),"2600-3600", H10>=3600,"3600+" ) -> 600-1600 | S10: =year(TODAY())-J10 -> 51 | T10: =ifs(AND(S10>=0,S10<=10),"New",AND(S10>10,S10<=30),"Mid",AND(S10>30,S10<=60),"Old",S10>60,"Very Old") -> Old | V10: NY | W10: =maxifs(Listings[Price],Listings[State],V10) -> 1498990 | Z10: Los Angeles | AA10: =AVERAGEIF(Listings[City],Z10,Listings[Price]) -> 815039.32 | AD10: Multi-Family | AE10: =Averageif(Listings[Property Type],AD10,Listings[Price]) -> 824386.87 | BH10: =IFERROR(__xludf.DUMMYFUNCTION("""COMPUTED_VALUE"""),204351.0) -> 204351 | BI10: =IFERROR(__xludf.DUMMYFUNCTION("""COMPUTED_VALUE"""),"7772 Maple Dr, Los Angeles, NY 94493") -> 7772 Maple Dr, Los Angeles, NY 94493 | BJ10: =IFERROR(__xludf.DUMMYFUNCTION("""COMPUTED_VALUE"""),"Los Angeles") -> Los Angeles | BK10: =IFERROR(__xludf.DUMMYFUNCTION("""COMPUTED_VALUE"""),94493.0) -> 94493 | BL10: =IFERROR(__xludf.DUMMYFUNCTION("""COMPUTED_VALUE"""),"NY") -> NY | BM10: =IFERROR(__xludf.DUMMYFUNCTION("""COMPUTED_VALUE"""),"4 bds") -> 4 bds | BN10: =IFERROR(__xludf.DUMMYFUNCTION("""COMPUTED_VALUE"""),"3 ba") -> 3 ba | BO10: =IFERROR(__xludf.DUMMYFUNCTION("""COMPUTED_VALUE"""),1540.0) -> 1540 | BP10: =IFERROR(__xludf.DUMMYFUNCTION("""COMPUTED_VALUE"""),4699.0) -> 4699 | BQ10: =IFERROR(__xludf.DUMMYFUNCTION("""COMPUTED_VALUE"""),1962.0) -> 1962 | BR10: =IFERROR(__xludf.DUMMYFUNCTION("""COMPUTED_VALUE"""),34.0) -> 34 | BS10: =IFERROR(__xludf.DUMMYFUNCTION("""COMPUTED_VALUE"""),"Multi-Family") -> Multi-Family | BT10: =IFERROR(__xludf.DUMMYFUNCTION("""COMPUTED_VALUE"""),"Z599335") -> Z599335 | BU10: =IFERROR(__xludf.DUMMYFUNCTION("""COMPUTED_VALUE"""),"Alex Johnson - Compass") -> Alex Johnson - Compass | BV10: =IFERROR(__xludf.DUMMYFUNCTION("""COMPUTED_VALUE"""),"Sold") -> Sold | BW10: =IFERROR(__xludf.DUMMYFUNCTION("""COMPUTED_VALUE"""),1.0) -> 1 | BX10: =IFERROR(__xludf.DUMMYFUNCTION("""COMPUTED_VALUE"""),"OK") -> OK | BY10: =IFERROR(__xludf.DUMMYFUNCTION("""COMPUTED_VALUE"""),"600-1600") -> 600-1600 | BZ10: =IFERROR(__xludf.DUMMYFUNCTION("""COMPUTED_VALUE"""),64.0) -> 64 | CA10: =IFERROR(__xludf.DUMMYFUNCTION("""COMPUTED_VALUE"""),"Very Old") -> Very Old
A11: 1356448 | B11: 8803 Maple Dr, San Diego, NY 57397 | C11: San Diego | D11: 57397 | E11: NY | F11: 2 bds | G11: 3 ba | H11: 2094 | I11: 2179 | J11: 1970 | K11: 111 | L11: Multi-Family | M11: Z264011 | N11: John Doe - RE/MAX | O11: Pending | P11: =COUNTIF(Analysis!$M$1:$M$3001,Analysis!$M11) -> 1 | Q11: =IF(COUNTIF(Analysis!$M$2:$M$3001,Analysis!$M11)>1,"Duplicate","OK") -> OK | R11: =IFS( AND(H11>=600, H11<1600),"600-1600", AND(H11>=1600, H11<2600),"1600-2600", AND(H11>=2600, H11<3600),"2600-3600", H11>=3600,"3600+" ) -> 1600-2600 | S11: =year(TODAY())-J11 -> 56 | T11: =ifs(AND(S11>=0,S11<=10),"New",AND(S11>10,S11<=30),"Mid",AND(S11>30,S11<=60),"Old",S11>60,"Very Old") -> Old | V11: TX | W11: =maxifs(Listings[Price],Listings[State],V11) -> 1499473 | Z11: San Francisco | AA11: =AVERAGEIF(Listings[City],Z11,Listings[Price]) -> 787924.53 | AD11: Condo | AE11: =Averageif(Listings[Property Type],AD11,Listings[Price]) -> 768002.41 | BH11: =IFERROR(__xludf.DUMMYFUNCTION("""COMPUTED_VALUE"""),970820.0) -> 970820 | BI11: =IFERROR(__xludf.DUMMYFUNCTION("""COMPUTED_VALUE"""),"865 Maple Dr, Sacramento, CA 97567") -> 865 Maple Dr, Sacramento, CA 97567 | BJ11: =IFERROR(__xludf.DUMMYFUNCTION("""COMPUTED_VALUE"""),"Sacramento") -> Sacramento | BK11: =IFERROR(__xludf.DUMMYFUNCTION("""COMPUTED_VALUE"""),97567.0) -> 97567 | BL11: =IFERROR(__xludf.DUMMYFUNCTION("""COMPUTED_VALUE"""),"CA") -> CA | BM11: =IFERROR(__xludf.DUMMYFUNCTION("""COMPUTED_VALUE"""),"5 bds") -> 5 bds | BN11: =IFERROR(__xludf.DUMMYFUNCTION("""COMPUTED_VALUE"""),"3 ba") -> 3 ba | BO11: =IFERROR(__xludf.DUMMYFUNCTION("""COMPUTED_VALUE"""),1506.0) -> 1506 | BP11: =IFERROR(__xludf.DUMMYFUNCTION("""COMPUTED_VALUE"""),3116.0) -> 3116 | BQ11: =IFERROR(__xludf.DUMMYFUNCTION("""COMPUTED_VALUE"""),2004.0) -> 2004 | BR11: =IFERROR(__xludf.DUMMYFUNCTION("""COMPUTED_VALUE"""),117.0) -> 117 | BS11: =IFERROR(__xludf.DUMMYFUNCTION("""COMPUTED_VALUE"""),"Townhouse") -> Townhouse | BT11: =IFERROR(__xludf.DUMMYFUNCTION("""COMPUTED_VALUE"""),"Z865226") -> Z865226 | BU11: =IFERROR(__xludf.DUMMYFUNCTION("""COMPUTED_VALUE"""),"Alex Johnson - Compass") -> Alex Johnson - Compass | BV11: =IFERROR(__xludf.DUMMYFUNCTION("""COMPUTED_VALUE"""),"Sold") -> Sold | BW11: =IFERROR(__xludf.DUMMYFUNCTION("""COMPUTED_VALUE"""),1.0) -> 1 | BX11: =IFERROR(__xludf.DUMMYFUNCTION("""COMPUTED_VALUE"""),"OK") -> OK | BY11: =IFERROR(__xludf.DUMMYFUNCTION("""COMPUTED_VALUE"""),"600-1600") -> 600-1600 | BZ11: =IFERROR(__xludf.DUMMYFUNCTION("""COMPUTED_VALUE"""),22.0) -> 22 | CA11: =IFERROR(__xludf.DUMMYFUNCTION("""COMPUTED_VALUE"""),"Mid") -> Mid
A12: 678604 | B12: 7535 Elm St, San Diego, FL 70072 | C12: San Diego | D12: 70072 | E12: FL | F12: 3 bds | G12: 3 ba | H12: 2350 | I12: 3341 | J12: 2013 | K12: 25 | L12: Multi-Family | M12: Z298501 | N12: John Doe - RE/MAX | O12: Pending | P12: =COUNTIF(Analysis!$M$1:$M$3001,Analysis!$M12) -> 1 | Q12: =IF(COUNTIF(Analysis!$M$2:$M$3001,Analysis!$M12)>1,"Duplicate","OK") -> OK | R12: =IFS( AND(H12>=600, H12<1600),"600-1600", AND(H12>=1600, H12<2600),"1600-2600", AND(H12>=2600, H12<3600),"2600-3600", H12>=3600,"3600+" ) -> 1600-2600 | S12: =year(TODAY())-J12 -> 13 | T12: =ifs(AND(S12>=0,S12<=10),"New",AND(S12>10,S12<=30),"Mid",AND(S12>30,S12<=60),"Old",S12>60,"Very Old") -> Mid | BH12: =IFERROR(__xludf.DUMMYFUNCTION("""COMPUTED_VALUE"""),1122084.0) -> 1122084 | BI12: =IFERROR(__xludf.DUMMYFUNCTION("""COMPUTED_VALUE"""),"6791 Oak Ave, San Diego, NY 80136") -> 6791 Oak Ave, San Diego, NY 80136 | BJ12: =IFERROR(__xludf.DUMMYFUNCTION("""COMPUTED_VALUE"""),"San Diego") -> San Diego | BK12: =IFERROR(__xludf.DUMMYFUNCTION("""COMPUTED_VALUE"""),80136.0) -> 80136 | BL12: =IFERROR(__xludf.DUMMYFUNCTION("""COMPUTED_VALUE"""),"NY") -> NY | BM12: =IFERROR(__xludf.DUMMYFUNCTION("""COMPUTED_VALUE"""),"6 bds") -> 6 bds | BN12: =IFERROR(__xludf.DUMMYFUNCTION("""COMPUTED_VALUE"""),"2 ba") -> 2 ba | BO12: =IFERROR(__xludf.DUMMYFUNCTION("""COMPUTED_VALUE"""),3061.0) -> 3061 | BP12: =IFERROR(__xludf.DUMMYFUNCTION("""COMPUTED_VALUE"""),8290.0) -> 8290 | BQ12: =IFERROR(__xludf.DUMMYFUNCTION("""COMPUTED_VALUE"""),2000.0) -> 2000 | BR12: =IFERROR(__xludf.DUMMYFUNCTION("""COMPUTED_VALUE"""),78.0) -> 78 | BS12: =IFERROR(__xludf.DUMMYFUNCTION("""COMPUTED_VALUE"""),"Townhouse") -> Townhouse | BT12: =IFERROR(__xludf.DUMMYFUNCTION("""COMPUTED_VALUE"""),"Z214122") -> Z214122 | BU12: =IFERROR(__xludf.DUMMYFUNCTION("""COMPUTED_VALUE"""),"Alex Johnson - Compass") -> Alex Johnson - Compass | BV12: =IFERROR(__xludf.DUMMYFUNCTION("""COMPUTED_VALUE"""),"Sold") -> Sold | BW12: =IFERROR(__xludf.DUMMYFUNCTION("""COMPUTED_VALUE"""),1.0) -> 1 | BX12: =IFERROR(__xludf.DUMMYFUNCTION("""COMPUTED_VALUE"""),"OK") -> OK | BY12: =IFERROR(__xludf.DUMMYFUNCTION("""COMPUTED_VALUE"""),"2600-3600") -> 2600-3600 | BZ12: =IFERROR(__xludf.DUMMYFUNCTION("""COMPUTED_VALUE"""),26.0) -> 26 | CA12: =IFERROR(__xludf.DUMMYFUNCTION("""COMPUTED_VALUE"""),"Mid") -> Mid
A13: 102028 | B13: 4880 Elm St, Fresno, CA 60495 | C13: Fresno | D13: 60495 | E13: CA | F13: 1 bds | G13: 2 ba | H13: 1824 | I13: 8908 | J13: 1975 | K13: 42 | L13: Townhouse | M13: Z103938 | N13: Jane Smith - Keller Williams | O13: For Sale | P13: =COUNTIF(Analysis!$M$1:$M$3001,Analysis!$M1512) -> 1 | Q13: =IF(COUNTIF(Analysis!$M$2:$M$3001,Analysis!$M1512)>1,"Duplicate","OK") -> OK | R13: =IFS( AND(H13>=600, H13<1600),"600-1600", AND(H13>=1600, H13<2600),"1600-2600", AND(H13>=2600, H13<3600),"2600-3600", H13>=3600,"3600+" ) -> 1600-2600 | S13: =year(TODAY())-J13 -> 51 | T13: =ifs(AND(S13>=0,S13<=10),"New",AND(S13>10,S13<=30),"Mid",AND(S13>30,S13<=60),"Old",S13>60,"Very Old") -> Old | BH13: =IFERROR(__xludf.DUMMYFUNCTION("""COMPUTED_VALUE"""),215904.0) -> 215904 | BI13: =IFERROR(__xludf.DUMMYFUNCTION("""COMPUTED_VALUE"""),"1429 Main St, San Diego, TX 63640") -> 1429 Main St, San Diego, TX 63640 | BJ13: =IFERROR(__xludf.DUMMYFUNCTION("""COMPUTED_VALUE"""),"San Diego") -> San Diego | BK13: =IFERROR(__xludf.DUMMYFUNCTION("""COMPUTED_VALUE"""),63640.0) -> 63640 | BL13: =IFERROR(__xludf.DUMMYFUNCTION("""COMPUTED_VALUE"""),"TX") -> TX | BM13: =IFERROR(__xludf.DUMMYFUNCTION("""COMPUTED_VALUE"""),"6 bds") -> 6 bds | BN13: =IFERROR(__xludf.DUMMYFUNCTION("""COMPUTED_VALUE"""),"4 ba") -> 4 ba | BO13: =IFERROR(__xludf.DUMMYFUNCTION("""COMPUTED_VALUE"""),2701.0) -> 2701 | BP13: =IFERROR(__xludf.DUMMYFUNCTION("""COMPUTED_VALUE"""),9476.0) -> 9476 | BQ13: =IFERROR(__xludf.DUMMYFUNCTION("""COMPUTED_VALUE"""),1995.0) -> 1995 | BR13: =IFERROR(__xludf.DUMMYFUNCTION("""COMPUTED_VALUE"""),47.0) -> 47 | BS13: =IFERROR(__xludf.DUMMYFUNCTION("""COMPUTED_VALUE"""),"Multi-Family") -> Multi-Family | BT13: =IFERROR(__xludf.DUMMYFUNCTION("""COMPUTED_VALUE"""),"Z501809") -> Z501809 | BU13: =IFERROR(__xludf.DUMMYFUNCTION("""COMPUTED_VALUE"""),"Alex Johnson - Compass") -> Alex Johnson - Compass | BV13: =IFERROR(__xludf.DUMMYFUNCTION("""COMPUTED_VALUE"""),"Sold") -> Sold | BW13: =IFERROR(__xludf.DUMMYFUNCTION("""COMPUTED_VALUE"""),1.0) -> 1 | BX13: =IFERROR(__xludf.DUMMYFUNCTION("""COMPUTED_VALUE"""),"OK") -> OK | BY13: =IFERROR(__xludf.DUMMYFUNCTION("""COMPUTED_VALUE"""),"2600-3600") -> 2600-3600 | BZ13: =IFERROR(__xludf.DUMMYFUNCTION("""COMPUTED_VALUE"""),31.0) -> 31 | CA13: =IFERROR(__xludf.DUMMYFUNCTION("""COMPUTED_VALUE"""),"Old") -> Old
A14: 645962 | B14: 9692 Maple Dr, Los Angeles, CA 91395 | C14: Los Angeles | D14: 91395 | E14: CA | F14: 4 bds | G14: 3 ba | H14: 2746 | I14: 8256 | J14: 2008 | K14: 11 | L14: Condo | M14: Z855977 | N14: Emily Davis - Century 21 | O14: Pending | P14: =COUNTIF(Analysis!$M$1:$M$3001,Analysis!$M14) -> 1 | Q14: =IF(COUNTIF(Analysis!$M$2:$M$3001,Analysis!$M14)>1,"Duplicate","OK") -> OK | R14: =IFS( AND(H14>=600, H14<1600),"600-1600", AND(H14>=1600, H14<2600),"1600-2600", AND(H14>=2600, H14<3600),"2600-3600", H14>=3600,"3600+" ) -> 2600-3600 | S14: =year(TODAY())-J14 -> 18 | T14: =ifs(AND(S14>=0,S14<=10),"New",AND(S14>10,S14<=30),"Mid",AND(S14>30,S14<=60),"Old",S14>60,"Very Old") -> Mid | BH14: =IFERROR(__xludf.DUMMYFUNCTION("""COMPUTED_VALUE"""),158429.0) -> 158429 | BI14: =IFERROR(__xludf.DUMMYFUNCTION("""COMPUTED_VALUE"""),"6067 Main St, Fresno, FL 51176") -> 6067 Main St, Fresno, FL 51176 | BJ14: =IFERROR(__xludf.DUMMYFUNCTION("""COMPUTED_VALUE"""),"Fresno") -> Fresno | BK14: =IFERROR(__xludf.DUMMYFUNCTION("""COMPUTED_VALUE"""),51176.0) -> 51176 | BL14: =IFERROR(__xludf.DUMMYFUNCTION("""COMPUTED_VALUE"""),"FL") -> FL | BM14: =IFERROR(__xludf.DUMMYFUNCTION("""COMPUTED_VALUE"""),"3 bds") -> 3 bds | BN14: =IFERROR(__xludf.DUMMYFUNCTION("""COMPUTED_VALUE"""),"3 ba") -> 3 ba | BO14: =IFERROR(__xludf.DUMMYFUNCTION("""COMPUTED_VALUE"""),3000.0) -> 3000 | BP14: =IFERROR(__xludf.DUMMYFUNCTION("""COMPUTED_VALUE"""),3035.0) -> 3035 | BQ14: =IFERROR(__xludf.DUMMYFUNCTION("""COMPUTED_VALUE"""),1950.0) -> 1950 | BR14: =IFERROR(__xludf.DUMMYFUNCTION("""COMPUTED_VALUE"""),84.0) -> 84 | BS14: =IFERROR(__xludf.DUMMYFUNCTION("""COMPUTED_VALUE"""),"Apartment") -> Apartment | BT14: =IFERROR(__xludf.DUMMYFUNCTION("""COMPUTED_VALUE"""),"Z382774") -> Z382774 | BU14: =IFERROR(__xludf.DUMMYFUNCTION("""COMPUTED_VALUE"""),"Alex Johnson - Compass") -> Alex Johnson - Compass | BV14: =IFERROR(__xludf.DUMMYFUNCTION("""COMPUTED_VALUE"""),"Sold") -> Sold | BW14: =IFERROR(__xludf.DUMMYFUNCTION("""COMPUTED_VALUE"""),1.0) -> 1 | BX14: =IFERROR(__xludf.DUMMYFUNCTION("""COMPUTED_VALUE"""),"OK") -> OK | BY14: =IFERROR(__xludf.DUMMYFUNCTION("""COMPUTED_VALUE"""),"2600-3600") -> 2600-3600 | BZ14: =IFERROR(__xludf.DUMMYFUNCTION("""COMPUTED_VALUE"""),76.0) -> 76 | CA14: =IFERROR(__xludf.DUMMYFUNCTION("""COMPUTED_VALUE"""),"Very Old") -> Very Old
A15: 575637 | B15: 905 Oak Ave, Sacramento, NY 28568 | C15: Sacramento | D15: 28568 | E15: NY | F15: 1 bds | G15: 4 ba | H15: 3387 | I15: 1740 | J15: 1966 | K15: 97 | L15: Condo | M15: Z166677 | N15: Jane Smith - Keller Williams | O15: Pending | P15: =COUNTIF(Analysis!$M$1:$M$3001,Analysis!$M15) -> 1 | Q15: =IF(COUNTIF(Analysis!$M$2:$M$3001,Analysis!$M15)>1,"Duplicate","OK") -> OK | R15: =IFS( AND(H15>=600, H15<1600),"600-1600", AND(H15>=1600, H15<2600),"1600-2600", AND(H15>=2600, H15<3600),"2600-3600", H15>=3600,"3600+" ) -> 2600-3600 | S15: =year(TODAY())-J15 -> 60 | T15: =ifs(AND(S15>=0,S15<=10),"New",AND(S15>10,S15<=30),"Mid",AND(S15>30,S15<=60),"Old",S15>60,"Very Old") -> Old | BH15: =IFERROR(__xludf.DUMMYFUNCTION("""COMPUTED_VALUE"""),1001011.0) -> 1001011 | BI15: =IFERROR(__xludf.DUMMYFUNCTION("""COMPUTED_VALUE"""),"1012 Maple Dr, San Diego, IL 69693") -> 1012 Maple Dr, San Diego, IL 69693 | BJ15: =IFERROR(__xludf.DUMMYFUNCTION("""COMPUTED_VALUE"""),"San Diego") -> San Diego | BK15: =IFERROR(__xludf.DUMMYFUNCTION("""COMPUTED_VALUE"""),69693.0) -> 69693 | BL15: =IFERROR(__xludf.DUMMYFUNCTION("""COMPUTED_VALUE"""),"IL") -> IL | BM15: =IFERROR(__xludf.DUMMYFUNCTION("""COMPUTED_VALUE"""),"6 bds") -> 6 bds | BN15: =IFERROR(__xludf.DUMMYFUNCTION("""COMPUTED_VALUE"""),"1 ba") -> 1 ba | BO15: =IFERROR(__xludf.DUMMYFUNCTION("""COMPUTED_VALUE"""),1905.0) -> 1905 | BP15: =IFERROR(__xludf.DUMMYFUNCTION("""COMPUTED_VALUE"""),4957.0) -> 4957 | BQ15: =IFERROR(__xludf.DUMMYFUNCTION("""COMPUTED_VALUE"""),1975.0) -> 1975 | BR15: =IFERROR(__xludf.DUMMYFUNCTION("""COMPUTED_VALUE"""),12.0) -> 12 | BS15: =IFERROR(__xludf.DUMMYFUNCTION("""COMPUTED_VALUE"""),"Apartment") -> Apartment | BT15: =IFERROR(__xludf.DUMMYFUNCTION("""COMPUTED_VALUE"""),"Z570340") -> Z570340 | BU15: =IFERROR(__xludf.DUMMYFUNCTION("""COMPUTED_VALUE"""),"Alex Johnson - Compass") -> Alex Johnson - Compass | BV15: =IFERROR(__xludf.DUMMYFUNCTION("""COMPUTED_VALUE"""),"Sold") -> Sold | BW15: =IFERROR(__xludf.DUMMYFUNCTION("""COMPUTED_VALUE"""),1.0) -> 1 | BX15: =IFERROR(__xludf.DUMMYFUNCTION("""COMPUTED_VALUE"""),"OK") -> OK | BY15: =IFERROR(__xludf.DUMMYFUNCTION("""COMPUTED_VALUE"""),"1600-2600") -> 1600-2600 | BZ15: =IFERROR(__xludf.DUMMYFUNCTION("""COMPUTED_VALUE"""),51.0) -> 51 | CA15: =IFERROR(__xludf.DUMMYFUNCTION("""COMPUTED_VALUE"""),"Old") -> Old
A16: 103682 | B16: 2786 Elm St, Fresno, NY 79620 | C16: Fresno | D16: 79620 | E16: NY | F16: 3 bds | G16: 4 ba | H16: 1451 | I16: 4606 | J16: 2001 | K16: 99 | L16: Single Family | M16: Z931895 | N16: Mike Lee - Coldwell Banker | O16: For Sale | P16: =COUNTIF(Analysis!$M$1:$M$3001,Analysis!$M1592) -> 1 | Q16: =IF(COUNTIF(Analysis!$M$2:$M$3001,Analysis!$M1592)>1,"Duplicate","OK") -> OK | R16: =IFS( AND(H16>=600, H16<1600),"600-1600", AND(H16>=1600, H16<2600),"1600-2600", AND(H16>=2600, H16<3600),"2600-3600", H16>=3600,"3600+" ) -> 600-1600 | S16: =year(TODAY())-J16 -> 25 | T16: =ifs(AND(S16>=0,S16<=10),"New",AND(S16>10,S16<=30),"Mid",AND(S16>30,S16<=60),"Old",S16>60,"Very Old") -> Mid | V16: No. Of Bedrooms | W16: Average Price | Z16: Area | AA16: Average Price | AD16: Property Type | AE16: Average Days on Market | BH16: =IFERROR(__xludf.DUMMYFUNCTION("""COMPUTED_VALUE"""),633891.0) -> 633891 | BI16: =IFERROR(__xludf.DUMMYFUNCTION("""COMPUTED_VALUE"""),"5092 Pine Rd, San Francisco, NY 21343") -> 5092 Pine Rd, San Francisco, NY 21343 | BJ16: =IFERROR(__xludf.DUMMYFUNCTION("""COMPUTED_VALUE"""),"San Francisco") -> San Francisco | BK16: =IFERROR(__xludf.DUMMYFUNCTION("""COMPUTED_VALUE"""),21343.0) -> 21343 | BL16: =IFERROR(__xludf.DUMMYFUNCTION("""COMPUTED_VALUE"""),"NY") -> NY | BM16: =IFERROR(__xludf.DUMMYFUNCTION("""COMPUTED_VALUE"""),"4 bds") -> 4 bds | BN16: =IFERROR(__xludf.DUMMYFUNCTION("""COMPUTED_VALUE"""),"4 ba") -> 4 ba | BO16: =IFERROR(__xludf.DUMMYFUNCTION("""COMPUTED_VALUE"""),3481.0) -> 3481 | BP16: =IFERROR(__xludf.DUMMYFUNCTION("""COMPUTED_VALUE"""),8346.0) -> 8346 | BQ16: =IFERROR(__xludf.DUMMYFUNCTION("""COMPUTED_VALUE"""),1967.0) -> 1967 | BR16: =IFERROR(__xludf.DUMMYFUNCTION("""COMPUTED_VALUE"""),14.0) -> 14 | BS16: =IFERROR(__xludf.DUMMYFUNCTION("""COMPUTED_VALUE"""),"Townhouse") -> Townhouse | BT16: =IFERROR(__xludf.DUMMYFUNCTION("""COMPUTED_VALUE"""),"Z177113") -> Z177113 | BU16: =IFERROR(__xludf.DUMMYFUNCTION("""COMPUTED_VALUE"""),"Alex Johnson - Compass") -> Alex Johnson - Compass | BV16: =IFERROR(__xludf.DUMMYFUNCTION("""COMPUTED_VALUE"""),"Sold") -> Sold | BW16: =IFERROR(__xludf.DUMMYFUNCTION("""COMPUTED_VALUE"""),1.0) -> 1 | BX16: =IFERROR(__xludf.DUMMYFUNCTION("""COMPUTED_VALUE"""),"OK") -> OK | BY16: =IFERROR(__xludf.DUMMYFUNCTION("""COMPUTED_VALUE"""),"2600-3600") -> 2600-3600 | BZ16: =IFERROR(__xludf.DUMMYFUNCTION("""COMPUTED_VALUE"""),59.0) -> 59 | CA16: =IFERROR(__xludf.DUMMYFUNCTION("""COMPUTED_VALUE"""),"Old") -> Old
A17: 1171629 | B17: 2475 Elm St, Sacramento, TX 63853 | C17: Sacramento | D17: 63853 | E17: TX | F17: 2 bds | G17: 4 ba | H17: 2351 | I17: 2275 | J17: 2007 | K17: 46 | L17: Condo | M17: Z325594 | N17: Alex Johnson - Compass | O17: For Sale | P17: =COUNTIF(Analysis!$M$1:$M$3001,Analysis!$M17) -> 1 | Q17: =IF(COUNTIF(Analysis!$M$2:$M$3001,Analysis!$M17)>1,"Duplicate","OK") -> OK | R17: =IFS( AND(H17>=600, H17<1600),"600-1600", AND(H17>=1600, H17<2600),"1600-2600", AND(H17>=2600, H17<3600),"2600-3600", H17>=3600,"3600+" ) -> 1600-2600 | S17: =year(TODAY())-J17 -> 19 | T17: =ifs(AND(S17>=0,S17<=10),"New",AND(S17>10,S17<=30),"Mid",AND(S17>30,S17<=60),"Old",S17>60,"Very Old") -> Mid | V17: 1 bds | W17: =AVERAGEIF(Listings[Bedrooms],V17,Listings[Price]) -> 829034.17 | Z17: 600-1600 | AA17: =AVERAGEIF(Listings[Area Category],Z17,Listings[Price]) -> 822055.82 | AD17: Townhouse | AE17: =IFERROR(__xludf.DUMMYFUNCTION("MODE(FILTER(Listings[Days on Market],Listings[Property Type]=AD17))"),83.0) -> 83 | BH17: =IFERROR(__xludf.DUMMYFUNCTION("""COMPUTED_VALUE"""),414153.0) -> 414153 | BI17: =IFERROR(__xludf.DUMMYFUNCTION("""COMPUTED_VALUE"""),"2336 Oak Ave, San Diego, FL 64992") -> 2336 Oak Ave, San Diego, FL 64992 | BJ17: =IFERROR(__xludf.DUMMYFUNCTION("""COMPUTED_VALUE"""),"San Diego") -> San Diego | BK17: =IFERROR(__xludf.DUMMYFUNCTION("""COMPUTED_VALUE"""),64992.0) -> 64992 | BL17: =IFERROR(__xludf.DUMMYFUNCTION("""COMPUTED_VALUE"""),"FL") -> FL | BM17: =IFERROR(__xludf.DUMMYFUNCTION("""COMPUTED_VALUE"""),"1 bds") -> 1 bds | BN17: =IFERROR(__xludf.DUMMYFUNCTION("""COMPUTED_VALUE"""),"4 ba") -> 4 ba | BO17: =IFERROR(__xludf.DUMMYFUNCTION("""COMPUTED_VALUE"""),1065.0) -> 1065 | BP17: =IFERROR(__xludf.DUMMYFUNCTION("""COMPUTED_VALUE"""),3682.0) -> 3682 | BQ17: =IFERROR(__xludf.DUMMYFUNCTION("""COMPUTED_VALUE"""),1956.0) -> 1956 | BR17: =IFERROR(__xludf.DUMMYFUNCTION("""COMPUTED_VALUE"""),113.0) -> 113 | BS17: =IFERROR(__xludf.DUMMYFUNCTION("""COMPUTED_VALUE"""),"Condo") -> Condo | BT17: =IFERROR(__xludf.DUMMYFUNCTION("""COMPUTED_VALUE"""),"Z384719") -> Z384719 | BU17: =IFERROR(__xludf.DUMMYFUNCTION("""COMPUTED_VALUE"""),"Alex Johnson - Compass") -> Alex Johnson - Compass | BV17: =IFERROR(__xludf.DUMMYFUNCTION("""COMPUTED_VALUE"""),"Sold") -> Sold | BW17: =IFERROR(__xludf.DUMMYFUNCTION("""COMPUTED_VALUE"""),1.0) -> 1 | BX17: =IFERROR(__xludf.DUMMYFUNCTION("""COMPUTED_VALUE"""),"OK") -> OK | BY17: =IFERROR(__xludf.DUMMYFUNCTION("""COMPUTED_VALUE"""),"600-1600") -> 600-1600 | BZ17: =IFERROR(__xludf.DUMMYFUNCTION("""COMPUTED_VALUE"""),70.0) -> 70 | CA17: =IFERROR(__xludf.DUMMYFUNCTION("""COMPUTED_VALUE"""),"Very Old") -> Very Old
A18: 698570 | B18: 5887 Oak Ave, Sacramento, CA 57513 | C18: Sacramento | D18: 57513 | E18: CA | F18: 3 bds | G18: 2 ba | H18: 722 | I18: 6443 | J18: 1953 | K18: 72 | L18: Apartment | M18: Z502987 | N18: Mike Lee - Coldwell Banker | O18: Sold | P18: =COUNTIF(Analysis!$M$1:$M$3001,Analysis!$M18) -> 1 | Q18: =IF(COUNTIF(Analysis!$M$2:$M$3001,Analysis!$M18)>1,"Duplicate","OK") -> OK | R18: =IFS( AND(H18>=600, H18<1600),"600-1600", AND(H18>=1600, H18<2600),"1600-2600", AND(H18>=2600, H18<3600),"2600-3600", H18>=3600,"3600+" ) -> 600-1600 | S18: =year(TODAY())-J18 -> 73 | T18: =ifs(AND(S18>=0,S18<=10),"New",AND(S18>10,S18<=30),"Mid",AND(S18>30,S18<=60),"Old",S18>60,"Very Old") -> Very Old | V18: 2 bds | W18: =AVERAGEIF(Listings[Bedrooms],V18,Listings[Price]) -> 841859.25 | Z18: 1600-2600 | AA18: =AVERAGEIF(Listings[Area Category],Z18,Listings[Price]) -> 831171.12 | AD18: Apartment | AE18: =IFERROR(__xludf.DUMMYFUNCTION("MODE(FILTER(Listings[Days on Market],Listings[Property Type]=AD18))"),120.0) -> 120 | BH18: =IFERROR(__xludf.DUMMYFUNCTION("""COMPUTED_VALUE"""),214127.0) -> 214127 | BI18: =IFERROR(__xludf.DUMMYFUNCTION("""COMPUTED_VALUE"""),"5310 Pine Rd, Fresno, FL 92602") -> 5310 Pine Rd, Fresno, FL 92602 | BJ18: =IFERROR(__xludf.DUMMYFUNCTION("""COMPUTED_VALUE"""),"Fresno") -> Fresno | BK18: =IFERROR(__xludf.DUMMYFUNCTION("""COMPUTED_VALUE"""),92602.0) -> 92602 | BL18: =IFERROR(__xludf.DUMMYFUNCTION("""COMPUTED_VALUE"""),"FL") -> FL | BM18: =IFERROR(__xludf.DUMMYFUNCTION("""COMPUTED_VALUE"""),"6 bds") -> 6 bds | BN18: =IFERROR(__xludf.DUMMYFUNCTION("""COMPUTED_VALUE"""),"4 ba") -> 4 ba | BO18: =IFERROR(__xludf.DUMMYFUNCTION("""COMPUTED_VALUE"""),2762.0) -> 2762 | BP18: =IFERROR(__xludf.DUMMYFUNCTION("""COMPUTED_VALUE"""),4177.0) -> 4177 | BQ18: =IFERROR(__xludf.DUMMYFUNCTION("""COMPUTED_VALUE"""),1952.0) -> 1952 | BR18: =IFERROR(__xludf.DUMMYFUNCTION("""COMPUTED_VALUE"""),69.0) -> 69 | BS18: =IFERROR(__xludf.DUMMYFUNCTION("""COMPUTED_VALUE"""),"Multi-Family") -> Multi-Family | BT18: =IFERROR(__xludf.DUMMYFUNCTION("""COMPUTED_VALUE"""),"Z923573") -> Z923573 | BU18: =IFERROR(__xludf.DUMMYFUNCTION("""COMPUTED_VALUE"""),"Alex Johnson - Compass") -> Alex Johnson - Compass | BV18: =IFERROR(__xludf.DUMMYFUNCTION("""COMPUTED_VALUE"""),"Sold") -> Sold | BW18: =IFERROR(__xludf.DUMMYFUNCTION("""COMPUTED_VALUE"""),1.0) -> 1 | BX18: =IFERROR(__xludf.DUMMYFUNCTION("""COMPUTED_VALUE"""),"OK") -> OK | BY18: =IFERROR(__xludf.DUMMYFUNCTION("""COMPUTED_VALUE"""),"2600-3600") -> 2600-3600 | BZ18: =IFERROR(__xludf.DUMMYFUNCTION("""COMPUTED_VALUE"""),74.0) -> 74 | CA18: =IFERROR(__xludf.DUMMYFUNCTION("""COMPUTED_VALUE"""),"Very Old") -> Very Old
A19: 534688 | B19: 3934 Elm St, San Francisco, TX 17359 | C19: San Francisco | D19: 17359 | E19: TX | F19: 3 bds | G19: 1 ba | H19: 2356 | I19: 3883 | J19: 1958 | K19: 114 | L19: Townhouse | M19: Z726231 | N19: John Doe - RE/MAX | O19: Pending | P19: =COUNTIF(Analysis!$M$1:$M$3001,Analysis!$M19) -> 1 | Q19: =IF(COUNTIF(Analysis!$M$2:$M$3001,Analysis!$M19)>1,"Duplicate","OK") -> OK | R19: =IFS( AND(H19>=600, H19<1600),"600-1600", AND(H19>=1600, H19<2600),"1600-2600", AND(H19>=2600, H19<3600),"2600-3600", H19>=3600,"3600+" ) -> 1600-2600 | S19: =year(TODAY())-J19 -> 68 | T19: =ifs(AND(S19>=0,S19<=10),"New",AND(S19>10,S19<=30),"Mid",AND(S19>30,S19<=60),"Old",S19>60,"Very Old") -> Very Old | V19: 3 bds | W19: =AVERAGEIF(Listings[Bedrooms],V19,Listings[Price]) -> 762070.09 | Z19: 2600-3600 | AA19: =AVERAGEIF(Listings[Area Category],Z19,Listings[Price]) -> 782539.76 | AD19: Single Family | AE19: =IFERROR(__xludf.DUMMYFUNCTION("MODE(FILTER(Listings[Days on Market],Listings[Property Type]=AD19))"),118.0) -> 118 | BH19: =IFERROR(__xludf.DUMMYFUNCTION("""COMPUTED_VALUE"""),925438.0) -> 925438 | BI19: =IFERROR(__xludf.DUMMYFUNCTION("""COMPUTED_VALUE"""),"6372 Oak Ave, Sacramento, CA 45299") -> 6372 Oak Ave, Sacramento, CA 45299 | BJ19: =IFERROR(__xludf.DUMMYFUNCTION("""COMPUTED_VALUE"""),"Sacramento") -> Sacramento | BK19: =IFERROR(__xludf.DUMMYFUNCTION("""COMPUTED_VALUE"""),45299.0) -> 45299 | BL19: =IFERROR(__xludf.DUMMYFUNCTION("""COMPUTED_VALUE"""),"CA") -> CA | BM19: =IFERROR(__xludf.DUMMYFUNCTION("""COMPUTED_VALUE"""),"2 bds") -> 2 bds | BN19: =IFERROR(__xludf.DUMMYFUNCTION("""COMPUTED_VALUE"""),"3 ba") -> 3 ba | BO19: =IFERROR(__xludf.DUMMYFUNCTION("""COMPUTED_VALUE"""),2307.0) -> 2307 | BP19: =IFERROR(__xludf.DUMMYFUNCTION("""COMPUTED_VALUE"""),7339.0) -> 7339 | BQ19: =IFERROR(__xludf.DUMMYFUNCTION("""COMPUTED_VALUE"""),2019.0) -> 2019 | BR19: =IFERROR(__xludf.DUMMYFUNCTION("""COMPUTED_VALUE"""),37.0) -> 37 | BS19: =IFERROR(__xludf.DUMMYFUNCTION("""COMPUTED_VALUE"""),"Apartment") -> Apartment | BT19: =IFERROR(__xludf.DUMMYFUNCTION("""COMPUTED_VALUE"""),"Z965755") -> Z965755 | BU19: =IFERROR(__xludf.DUMMYFUNCTION("""COMPUTED_VALUE"""),"Alex Johnson - Compass") -> Alex Johnson - Compass | BV19: =IFERROR(__xludf.DUMMYFUNCTION("""COMPUTED_VALUE"""),"Sold") -> Sold | BW19: =IFERROR(__xludf.DUMMYFUNCTION("""COMPUTED_VALUE"""),1.0) -> 1 | BX19: =IFERROR(__xludf.DUMMYFUNCTION("""COMPUTED_VALUE"""),"OK") -> OK | BY19: =IFERROR(__xludf.DUMMYFUNCTION("""COMPUTED_VALUE"""),"1600-2600") -> 1600-2600 | BZ19: =IFERROR(__xludf.DUMMYFUNCTION("""COMPUTED_VALUE"""),7.0) -> 7 | CA19: =IFERROR(__xludf.DUMMYFUNCTION("""COMPUTED_VALUE"""),"New") -> New
A20: 1108288 | B20: 3087 Maple Dr, Los Angeles, NY 11690 | C20: Los Angeles | D20: 11690 | E20: NY | F20: 6 bds | G20: 3 ba | H20: 1156 | I20: 1218 | J20: 1958 | K20: 28 | L20: Condo | M20: Z302684 | N20: Emily Davis - Century 21 | O20: Sold | P20: =COUNTIF(Analysis!$M$1:$M$3001,Analysis!$M20) -> 1 | Q20: =IF(COUNTIF(Analysis!$M$2:$M$3001,Analysis!$M20)>1,"Duplicate","OK") -> OK | R20: =IFS( AND(H20>=600, H20<1600),"600-1600", AND(H20>=1600, H20<2600),"1600-2600", AND(H20>=2600, H20<3600),"2600-3600", H20>=3600,"3600+" ) -> 600-1600 | S20: =year(TODAY())-J20 -> 68 | T20: =ifs(AND(S20>=0,S20<=10),"New",AND(S20>10,S20<=30),"Mid",AND(S20>30,S20<=60),"Old",S20>60,"Very Old") -> Very Old | V20: 4 bds | W20: =AVERAGEIF(Listings[Bedrooms],V20,Listings[Price]) -> 829111.84 | Z20: 3600+ | AA20: =AVERAGEIF(Listings[Area Category],Z20,Listings[Price]) -> 800382.54 | AD20: Multi-Family | AE20: =IFERROR(__xludf.DUMMYFUNCTION("MODE(FILTER(Listings[Days on Market],Listings[Property Type]=AD20))"),38.0) -> 38 | BH20: =IFERROR(__xludf.DUMMYFUNCTION("""COMPUTED_VALUE"""),913878.0) -> 913878 | BI20: =IFERROR(__xludf.DUMMYFUNCTION("""COMPUTED_VALUE"""),"1656 Oak Ave, Sacramento, FL 29610") -> 1656 Oak Ave, Sacramento, FL 29610 | BJ20: =IFERROR(__xludf.DUMMYFUNCTION("""COMPUTED_VALUE"""),"Sacramento") -> Sacramento | BK20: =IFERROR(__xludf.DUMMYFUNCTION("""COMPUTED_VALUE"""),29610.0) -> 29610 | BL20: =IFERROR(__xludf.DUMMYFUNCTION("""COMPUTED_VALUE"""),"FL") -> FL | BM20: =IFERROR(__xludf.DUMMYFUNCTION("""COMPUTED_VALUE"""),"2 bds") -> 2 bds | BN20: =IFERROR(__xludf.DUMMYFUNCTION("""COMPUTED_VALUE"""),"1 ba") -> 1 ba | BO20: =IFERROR(__xludf.DUMMYFUNCTION("""COMPUTED_VALUE"""),3288.0) -> 3288 | BP20: =IFERROR(__xludf.DUMMYFUNCTION("""COMPUTED_VALUE"""),1472.0) -> 1472 | BQ20: =IFERROR(__xludf.DUMMYFUNCTION("""COMPUTED_VALUE"""),1984.0) -> 1984 | BR20: =IFERROR(__xludf.DUMMYFUNCTION("""COMPUTED_VALUE"""),38.0) -> 38 | BS20: =IFERROR(__xludf.DUMMYFUNCTION("""COMPUTED_VALUE"""),"Multi-Family") -> Multi-Family | BT20: =IFERROR(__xludf.DUMMYFUNCTION("""COMPUTED_VALUE"""),"Z856614") -> Z856614 | BU20: =IFERROR(__xludf.DUMMYFUNCTION("""COMPUTED_VALUE"""),"Alex Johnson - Compass") -> Alex Johnson - Compass | BV20: =IFERROR(__xludf.DUMMYFUNCTION("""COMPUTED_VALUE"""),"Sold") -> Sold | BW20: =IFERROR(__xludf.DUMMYFUNCTION("""COMPUTED_VALUE"""),1.0) -> 1 | BX20: =IFERROR(__xludf.DUMMYFUNCTION("""COMPUTED_VALUE"""),"OK") -> OK | BY20: =IFERROR(__xludf.DUMMYFUNCTION("""COMPUTED_VALUE"""),"2600-3600") -> 2600-3600 | BZ20: =IFERROR(__xludf.DUMMYFUNCTION("""COMPUTED_VALUE"""),42.0) -> 42 | CA20: =IFERROR(__xludf.DUMMYFUNCTION("""COMPUTED_VALUE"""),"Old") -> Old
A21: 1173697 | B21: 4360 Maple Dr, Los Angeles, TX 97442 | C21: Los Angeles | D21: 97442 | E21: TX | F21: 2 bds | G21: 4 ba | H21: 1554 | I21: 9408 | J21: 1982 | K21: 1 | L21: Multi-Family | M21: Z879412 | N21: Mike Lee - Coldwell Banker | O21: Pending | P21: =COUNTIF(Analysis!$M$1:$M$3001,Analysis!$M21) -> 1 | Q21: =IF(COUNTIF(Analysis!$M$2:$M$3001,Analysis!$M21)>1,"Duplicate","OK") -> OK | R21: =IFS( AND(H21>=600, H21<1600),"600-1600", AND(H21>=1600, H21<2600),"1600-2600", AND(H21>=2600, H21<3600),"2600-3600", H21>=3600,"3600+" ) -> 600-1600 | S21: =year(TODAY())-J21 -> 44 | T21: =ifs(AND(S21>=0,S21<=10),"New",AND(S21>10,S21<=30),"Mid",AND(S21>30,S21<=60),"Old",S21>60,"Very Old") -> Old | V21: 5 bds | W21: =AVERAGEIF(Listings[Bedrooms],V21,Listings[Price]) -> 792353.99 | AD21: Condo | AE21: =IFERROR(__xludf.DUMMYFUNCTION("MODE(FILTER(Listings[Days on Market],Listings[Property Type]=AD21))"),18.0) -> 18 | BH21: =IFERROR(__xludf.DUMMYFUNCTION("""COMPUTED_VALUE"""),672952.0) -> 672952 | BI21: =IFERROR(__xludf.DUMMYFUNCTION("""COMPUTED_VALUE"""),"7575 Elm St, San Diego, NY 48097") -> 7575 Elm St, San Diego, NY 48097 | BJ21: =IFERROR(__xludf.DUMMYFUNCTION("""COMPUTED_VALUE"""),"San Diego") -> San Diego | BK21: =IFERROR(__xludf.DUMMYFUNCTION("""COMPUTED_VALUE"""),48097.0) -> 48097 | BL21: =IFERROR(__xludf.DUMMYFUNCTION("""COMPUTED_VALUE"""),"NY") -> NY | BM21: =IFERROR(__xludf.DUMMYFUNCTION("""COMPUTED_VALUE"""),"3 bds") -> 3 bds | BN21: =IFERROR(__xludf.DUMMYFUNCTION("""COMPUTED_VALUE"""),"4 ba") -> 4 ba | BO21: =IFERROR(__xludf.DUMMYFUNCTION("""COMPUTED_VALUE"""),1166.0) -> 1166 | BP21: =IFERROR(__xludf.DUMMYFUNCTION("""COMPUTED_VALUE"""),6068.0) -> 6068 | BQ21: =IFERROR(__xludf.DUMMYFUNCTION("""COMPUTED_VALUE"""),2002.0) -> 2002 | BR21: =IFERROR(__xludf.DUMMYFUNCTION("""COMPUTED_VALUE"""),34.0) -> 34 | BS21: =IFERROR(__xludf.DUMMYFUNCTION("""COMPUTED_VALUE"""),"Single Family") -> Single Family | BT21: =IFERROR(__xludf.DUMMYFUNCTION("""COMPUTED_VALUE"""),"Z119872") -> Z119872 | BU21: =IFERROR(__xludf.DUMMYFUNCTION("""COMPUTED_VALUE"""),"Alex Johnson - Compass") -> Alex Johnson - Compass | BV21: =IFERROR(__xludf.DUMMYFUNCTION("""COMPUTED_VALUE"""),"Sold") -> Sold | BW21: =IFERROR(__xludf.DUMMYFUNCTION("""COMPUTED_VALUE"""),1.0) -> 1 | BX21: =IFERROR(__xludf.DUMMYFUNCTION("""COMPUTED_VALUE"""),"OK") -> OK | BY21: =IFERROR(__xludf.DUMMYFUNCTION("""COMPUTED_VALUE"""),"600-1600") -> 600-1600 | BZ21: =IFERROR(__xludf.DUMMYFUNCTION("""COMPUTED_VALUE"""),24.0) -> 24 | CA21: =IFERROR(__xludf.DUMMYFUNCTION("""COMPUTED_VALUE"""),"Mid") -> Mid
A22: 980716 | B22: 8332 Oak Ave, Los Angeles, IL 12888 | C22: Los Angeles | D22: 12888 | E22: IL | F22: 2 bds | G22: 2 ba | H22: 982 | I22: 7527 | J22: 1983 | K22: 58 | L22: Multi-Family | M22: Z433130 | N22: Jane Smith - Keller Williams | O22: Sold | P22: =COUNTIF(Analysis!$M$1:$M$3001,Analysis!$M22) -> 1 | Q22: =IF(COUNTIF(Analysis!$M$2:$M$3001,Analysis!$M22)>1,"Duplicate","OK") -> OK | R22: =IFS( AND(H22>=600, H22<1600),"600-1600", AND(H22>=1600, H22<2600),"1600-2600", AND(H22>=2600, H22<3600),"2600-3600", H22>=3600,"3600+" ) -> 600-1600 | S22: =year(TODAY())-J22 -> 43 | T22: =ifs(AND(S22>=0,S22<=10),"New",AND(S22>10,S22<=30),"Mid",AND(S22>30,S22<=60),"Old",S22>60,"Very Old") -> Old | V22: 6 bds | W22: =AVERAGEIF(Listings[Bedrooms],V22,Listings[Price]) -> 810241.61 | BH22: =IFERROR(__xludf.DUMMYFUNCTION("""COMPUTED_VALUE"""),144964.0) -> 144964 | BI22: =IFERROR(__xludf.DUMMYFUNCTION("""COMPUTED_VALUE"""),"6550 Main St, Sacramento, IL 81788") -> 6550 Main St, Sacramento, IL 81788 | BJ22: =IFERROR(__xludf.DUMMYFUNCTION("""COMPUTED_VALUE"""),"Sacramento") -> Sacramento | BK22: =IFERROR(__xludf.DUMMYFUNCTION("""COMPUTED_VALUE"""),81788.0) -> 81788 | BL22: =IFERROR(__xludf.DUMMYFUNCTION("""COMPUTED_VALUE"""),"IL") -> IL | BM22: =IFERROR(__xludf.DUMMYFUNCTION("""COMPUTED_VALUE"""),"5 bds") -> 5 bds | BN22: =IFERROR(__xludf.DUMMYFUNCTION("""COMPUTED_VALUE"""),"3 ba") -> 3 ba | BO22: =IFERROR(__xludf.DUMMYFUNCTION("""COMPUTED_VALUE"""),1141.0) -> 1141 | BP22: =IFERROR(__xludf.DUMMYFUNCTION("""COMPUTED_VALUE"""),8933.0) -> 8933 | BQ22: =IFERROR(__xludf.DUMMYFUNCTION("""COMPUTED_VALUE"""),1994.0) -> 1994 | BR22: =IFERROR(__xludf.DUMMYFUNCTION("""COMPUTED_VALUE"""),62.0) -> 62 | BS22: =IFERROR(__xludf.DUMMYFUNCTION("""COMPUTED_VALUE"""),"Apartment") -> Apartment | BT22: =IFERROR(__xludf.DUMMYFUNCTION("""COMPUTED_VALUE"""),"Z515391") -> Z515391 | BU22: =IFERROR(__xludf.DUMMYFUNCTION("""COMPUTED_VALUE"""),"Alex Johnson - Compass") -> Alex Johnson - Compass | BV22: =IFERROR(__xludf.DUMMYFUNCTION("""COMPUTED_VALUE"""),"Sold") -> Sold | BW22: =IFERROR(__xludf.DUMMYFUNCTION("""COMPUTED_VALUE"""),1.0) -> 1 | BX22: =IFERROR(__xludf.DUMMYFUNCTION("""COMPUTED_VALUE"""),"OK") -> OK | BY22: =IFERROR(__xludf.DUMMYFUNCTION("""COMPUTED_VALUE"""),"600-1600") -> 600-1600 | BZ22: =IFERROR(__xludf.DUMMYFUNCTION("""COMPUTED_VALUE"""),32.0) -> 32 | CA22: =IFERROR(__xludf.DUMMYFUNCTION("""COMPUTED_VALUE"""),"Old") -> Old
A23: 527238 | B23: 4702 Pine Rd, Los Angeles, NY 63443 | C23: Los Angeles | D23: 63443 | E23: NY | F23: 4 bds | G23: 4 ba | H23: 3164 | I23: 9694 | J23: 1955 | K23: 33 | L23: Condo | M23: Z835234 | N23: Jane Smith - Keller Williams | O23: Pending | P23: =COUNTIF(Analysis!$M$1:$M$3001,Analysis!$M23) -> 1 | Q23: =IF(COUNTIF(Analysis!$M$2:$M$3001,Analysis!$M23)>1,"Duplicate","OK") -> OK | R23: =IFS( AND(H23>=600, H23<1600),"600-1600", AND(H23>=1600, H23<2600),"1600-2600", AND(H23>=2600, H23<3600),"2600-3600", H23>=3600,"3600+" ) -> 2600-3600 | S23: =year(TODAY())-J23 -> 71 | T23: =ifs(AND(S23>=0,S23<=10),"New",AND(S23>10,S23<=30),"Mid",AND(S23>30,S23<=60),"Old",S23>60,"Very Old") -> Very Old | BH23: =IFERROR(__xludf.DUMMYFUNCTION("""COMPUTED_VALUE"""),159682.0) -> 159682 | BI23: =IFERROR(__xludf.DUMMYFUNCTION("""COMPUTED_VALUE"""),"5514 Main St, Sacramento, CA 63062") -> 5514 Main St, Sacramento, CA 63062 | BJ23: =IFERROR(__xludf.DUMMYFUNCTION("""COMPUTED_VALUE"""),"Sacramento") -> Sacramento | BK23: =IFERROR(__xludf.DUMMYFUNCTION("""COMPUTED_VALUE"""),63062.0) -> 63062 | BL23: =IFERROR(__xludf.DUMMYFUNCTION("""COMPUTED_VALUE"""),"CA") -> CA | BM23: =IFERROR(__xludf.DUMMYFUNCTION("""COMPUTED_VALUE"""),"3 bds") -> 3 bds | BN23: =IFERROR(__xludf.DUMMYFUNCTION("""COMPUTED_VALUE"""),"1 ba") -> 1 ba | BO23: =IFERROR(__xludf.DUMMYFUNCTION("""COMPUTED_VALUE"""),3421.0) -> 3421 | BP23: =IFERROR(__xludf.DUMMYFUNCTION("""COMPUTED_VALUE"""),2996.0) -> 2996 | BQ23: =IFERROR(__xludf.DUMMYFUNCTION("""COMPUTED_VALUE"""),1992.0) -> 1992 | BR23: =IFERROR(__xludf.DUMMYFUNCTION("""COMPUTED_VALUE"""),39.0) -> 39 | BS23: =IFERROR(__xludf.DUMMYFUNCTION("""COMPUTED_VALUE"""),"Multi-Family") -> Multi-Family | BT23: =IFERROR(__xludf.DUMMYFUNCTION("""COMPUTED_VALUE"""),"Z762393") -> Z762393 | BU23: =IFERROR(__xludf.DUMMYFUNCTION("""COMPUTED_VALUE"""),"Alex Johnson - Compass") -> Alex Johnson - Compass | BV23: =IFERROR(__xludf.DUMMYFUNCTION("""COMPUTED_VALUE"""),"Sold") -> Sold | BW23: =IFERROR(__xludf.DUMMYFUNCTION("""COMPUTED_VALUE"""),1.0) -> 1 | BX23: =IFERROR(__xludf.DUMMYFUNCTION("""COMPUTED_VALUE"""),"OK") -> OK | BY23: =IFERROR(__xludf.DUMMYFUNCTION("""COMPUTED_VALUE"""),"2600-3600") -> 2600-3600 | BZ23: =IFERROR(__xludf.DUMMYFUNCTION("""COMPUTED_VALUE"""),34.0) -> 34 | CA23: =IFERROR(__xludf.DUMMYFUNCTION("""COMPUTED_VALUE"""),"Old") -> Old
A24: 104351 | B24: 289 Elm St, Fresno, FL 37362 | C24: Fresno | D24: 37362 | E24: FL | F24: 5 bds | G24: 4 ba | H24: 3663 | I24: 8122 | J24: 1989 | K24: 68 | L24: Apartment | M24: Z828424 | N24: John Doe - RE/MAX | O24: Pending | P24: =COUNTIF(Analysis!$M$1:$M$3001,Analysis!$M2499) -> 1 | Q24: =IF(COUNTIF(Analysis!$M$2:$M$3001,Analysis!$M2499)>1,"Duplicate","OK") -> OK | R24: =IFS( AND(H24>=600, H24<1600),"600-1600", AND(H24>=1600, H24<2600),"1600-2600", AND(H24>=2600, H24<3600),"2600-3600", H24>=3600,"3600+" ) -> 3600+ | S24: =year(TODAY())-J24 -> 37 | T24: =ifs(AND(S24>=0,S24<=10),"New",AND(S24>10,S24<=30),"Mid",AND(S24>30,S24<=60),"Old",S24>60,"Very Old") -> Old | BH24: =IFERROR(__xludf.DUMMYFUNCTION("""COMPUTED_VALUE"""),830918.0) -> 830918 | BI24: =IFERROR(__xludf.DUMMYFUNCTION("""COMPUTED_VALUE"""),"3517 Main St, Los Angeles, NY 68268") -> 3517 Main St, Los Angeles, NY 68268 | BJ24: =IFERROR(__xludf.DUMMYFUNCTION("""COMPUTED_VALUE"""),"Los Angeles") -> Los Angeles | BK24: =IFERROR(__xludf.DUMMYFUNCTION("""COMPUTED_VALUE"""),68268.0) -> 68268 | BL24: =IFERROR(__xludf.DUMMYFUNCTION("""COMPUTED_VALUE"""),"NY") -> NY | BM24: =IFERROR(__xludf.DUMMYFUNCTION("""COMPUTED_VALUE"""),"3 bds") -> 3 bds | BN24: =IFERROR(__xludf.DUMMYFUNCTION("""COMPUTED_VALUE"""),"3 ba") -> 3 ba | BO24: =IFERROR(__xludf.DUMMYFUNCTION("""COMPUTED_VALUE"""),1392.0) -> 1392 | BP24: =IFERROR(__xludf.DUMMYFUNCTION("""COMPUTED_VALUE"""),3648.0) -> 3648 | BQ24: =IFERROR(__xludf.DUMMYFUNCTION("""COMPUTED_VALUE"""),1997.0) -> 1997 | BR24: =IFERROR(__xludf.DUMMYFUNCTION("""COMPUTED_VALUE"""),68.0) -> 68 | BS24: =IFERROR(__xludf.DUMMYFUNCTION("""COMPUTED_VALUE"""),"Townhouse") -> Townhouse | BT24: =IFERROR(__xludf.DUMMYFUNCTION("""COMPUTED_VALUE"""),"Z684839") -> Z684839 | BU24: =IFERROR(__xludf.DUMMYFUNCTION("""COMPUTED_VALUE"""),"Alex Johnson - Compass") -> Alex Johnson - Compass | BV24: =IFERROR(__xludf.DUMMYFUNCTION("""COMPUTED_VALUE"""),"Sold") -> Sold | BW24: =IFERROR(__xludf.DUMMYFUNCTION("""COMPUTED_VALUE"""),1.0) -> 1 | BX24: =IFERROR(__xludf.DUMMYFUNCTION("""COMPUTED_VALUE"""),"OK") -> OK | BY24: =IFERROR(__xludf.DUMMYFUNCTION("""COMPUTED_VALUE"""),"600-1600") -> 600-1600 | BZ24: =IFERROR(__xludf.DUMMYFUNCTION("""COMPUTED_VALUE"""),29.0) -> 29 | CA24: =IFERROR(__xludf.DUMMYFUNCTION("""COMPUTED_VALUE"""),"Mid") -> Mid
A25: 1381949 | B25: 9953 Maple Dr, San Francisco, TX 33081 | C25: San Francisco | D25: 33081 | E25: TX | F25: 4 bds | G25: 4 ba | H25: 2966 | I25: 2421 | J25: 1997 | K25: 38 | L25: Single Family | M25: Z166756 | N25: Emily Davis - Century 21 | O25: Sold | P25: =COUNTIF(Analysis!$M$1:$M$3001,Analysis!$M25) -> 1 | Q25: =IF(COUNTIF(Analysis!$M$2:$M$3001,Analysis!$M25)>1,"Duplicate","OK") -> OK | R25: =IFS( AND(H25>=600, H25<1600),"600-1600", AND(H25>=1600, H25<2600),"1600-2600", AND(H25>=2600, H25<3600),"2600-3600", H25>=3600,"3600+" ) -> 2600-3600 | S25: =year(TODAY())-J25 -> 29 | T25: =ifs(AND(S25>=0,S25<=10),"New",AND(S25>10,S25<=30),"Mid",AND(S25>30,S25<=60),"Old",S25>60,"Very Old") -> Mid | BH25: =IFERROR(__xludf.DUMMYFUNCTION("""COMPUTED_VALUE"""),1413534.0) -> 1413534 | BI25: =IFERROR(__xludf.DUMMYFUNCTION("""COMPUTED_VALUE"""),"1807 Maple Dr, San Francisco, CA 33992") -> 1807 Maple Dr, San Francisco, CA 33992 | BJ25: =IFERROR(__xludf.DUMMYFUNCTION("""COMPUTED_VALUE"""),"San Francisco") -> San Francisco | BK25: =IFERROR(__xludf.DUMMYFUNCTION("""COMPUTED_VALUE"""),33992.0) -> 33992 | BL25: =IFERROR(__xludf.DUMMYFUNCTION("""COMPUTED_VALUE"""),"CA") -> CA | BM25: =IFERROR(__xludf.DUMMYFUNCTION("""COMPUTED_VALUE"""),"6 bds") -> 6 bds | BN25: =IFERROR(__xludf.DUMMYFUNCTION("""COMPUTED_VALUE"""),"2 ba") -> 2 ba | BO25: =IFERROR(__xludf.DUMMYFUNCTION("""COMPUTED_VALUE"""),2609.0) -> 2609 | BP25: =IFERROR(__xludf.DUMMYFUNCTION("""COMPUTED_VALUE"""),6952.0) -> 6952 | BQ25: =IFERROR(__xludf.DUMMYFUNCTION("""COMPUTED_VALUE"""),1967.0) -> 1967 | BR25: =IFERROR(__xludf.DUMMYFUNCTION("""COMPUTED_VALUE"""),38.0) -> 38 | BS25: =IFERROR(__xludf.DUMMYFUNCTION("""COMPUTED_VALUE"""),"Condo") -> Condo | BT25: =IFERROR(__xludf.DUMMYFUNCTION("""COMPUTED_VALUE"""),"Z689262") -> Z689262 | BU25: =IFERROR(__xludf.DUMMYFUNCTION("""COMPUTED_VALUE"""),"Alex Johnson - Compass") -> Alex Johnson - Compass | BV25: =IFERROR(__xludf.DUMMYFUNCTION("""COMPUTED_VALUE"""),"Sold") -> Sold | BW25: =IFERROR(__xludf.DUMMYFUNCTION("""COMPUTED_VALUE"""),1.0) -> 1 | BX25: =IFERROR(__xludf.DUMMYFUNCTION("""COMPUTED_VALUE"""),"OK") -> OK | BY25: =IFERROR(__xludf.DUMMYFUNCTION("""COMPUTED_VALUE"""),"2600-3600") -> 2600-3600 | BZ25: =IFERROR(__xludf.DUMMYFUNCTION("""COMPUTED_VALUE"""),59.0) -> 59 | CA25: =IFERROR(__xludf.DUMMYFUNCTION("""COMPUTED_VALUE"""),"Old") -> Old
A26: 898597 | B26: 3530 Oak Ave, Sacramento, FL 16851 | C26: Sacramento | D26: 16851 | E26: FL | F26: 6 bds | G26: 3 ba | H26: 3814 | I26: 2093 | J26: 1957 | K26: 71 | L26: Condo | M26: Z574837 | N26: Jane Smith - Keller Williams | O26: Sold | P26: =COUNTIF(Analysis!$M$1:$M$3001,Analysis!$M26) -> 1 | Q26: =IF(COUNTIF(Analysis!$M$2:$M$3001,Analysis!$M26)>1,"Duplicate","OK") -> OK | R26: =IFS( AND(H26>=600, H26<1600),"600-1600", AND(H26>=1600, H26<2600),"1600-2600", AND(H26>=2600, H26<3600),"2600-3600", H26>=3600,"3600+" ) -> 3600+ | S26: =year(TODAY())-J26 -> 69 | T26: =ifs(AND(S26>=0,S26<=10),"New",AND(S26>10,S26<=30),"Mid",AND(S26>30,S26<=60),"Old",S26>60,"Very Old") -> Very Old | BH26: =IFERROR(__xludf.DUMMYFUNCTION("""COMPUTED_VALUE"""),727584.0) -> 727584 | BI26: =IFERROR(__xludf.DUMMYFUNCTION("""COMPUTED_VALUE"""),"2285 Pine Rd, Los Angeles, IL 68343") -> 2285 Pine Rd, Los Angeles, IL 68343 | BJ26: =IFERROR(__xludf.DUMMYFUNCTION("""COMPUTED_VALUE"""),"Los Angeles") -> Los Angeles | BK26: =IFERROR(__xludf.DUMMYFUNCTION("""COMPUTED_VALUE"""),68343.0) -> 68343 | BL26: =IFERROR(__xludf.DUMMYFUNCTION("""COMPUTED_VALUE"""),"IL") -> IL | BM26: =IFERROR(__xludf.DUMMYFUNCTION("""COMPUTED_VALUE"""),"5 bds") -> 5 bds | BN26: =IFERROR(__xludf.DUMMYFUNCTION("""COMPUTED_VALUE"""),"1 ba") -> 1 ba | BO26: =IFERROR(__xludf.DUMMYFUNCTION("""COMPUTED_VALUE"""),620.0) -> 620 | BP26: =IFERROR(__xludf.DUMMYFUNCTION("""COMPUTED_VALUE"""),3573.0) -> 3573 | BQ26: =IFERROR(__xludf.DUMMYFUNCTION("""COMPUTED_VALUE"""),2008.0) -> 2008 | BR26: =IFERROR(__xludf.DUMMYFUNCTION("""COMPUTED_VALUE"""),23.0) -> 23 | BS26: =IFERROR(__xludf.DUMMYFUNCTION("""COMPUTED_VALUE"""),"Townhouse") -> Townhouse | BT26: =IFERROR(__xludf.DUMMYFUNCTION("""COMPUTED_VALUE"""),"Z847985") -> Z847985 | BU26: =IFERROR(__xludf.DUMMYFUNCTION("""COMPUTED_VALUE"""),"Alex Johnson - Compass") -> Alex Johnson - Compass | BV26: =IFERROR(__xludf.DUMMYFUNCTION("""COMPUTED_VALUE"""),"Sold") -> Sold | BW26: =IFERROR(__xludf.DUMMYFUNCTION("""COMPUTED_VALUE"""),1.0) -> 1 | BX26: =IFERROR(__xludf.DUMMYFUNCTION("""COMPUTED_VALUE"""),"OK") -> OK | BY26: =IFERROR(__xludf.DUMMYFUNCTION("""COMPUTED_VALUE"""),"600-1600") -> 600-1600 | BZ26: =IFERROR(__xludf.DUMMYFUNCTION("""COMPUTED_VALUE"""),18.0) -> 18 | CA26: =IFERROR(__xludf.DUMMYFUNCTION("""COMPUTED_VALUE"""),"Mid") -> Mid
